Workbook
Name _Hlk187915364: '4.HT PCCC'!$C$291
Name _Toc177393993: '4.HT PCCC'!$C$523
Name _Toc177393994: '4.HT PCCC'!$C$711
Name _Toc469402498: '4.HT PCCC'!$C$558
Name _Toc469402515: '4.HT PCCC'!$C$559
Name _Toc469402516: '4.HT PCCC'!$C$560
Name _Toc469402542: '4.HT PCCC'!$C$722
Name _Toc469402543: '4.HT PCCC'!$C$723
Name _Toc469402544: '4.HT PCCC'!$C$724
Name _Toc469402545: '4.HT PCCC'!$C$725
Name _Toc469402546: '4.HT PCCC'!$C$727
Name _Toc469402547: '4.HT PCCC'!$C$728
Name _Toc469402548: '4.HT PCCC'!$C$729
Name _Toc469402549: '4.HT PCCC'!$C$730
Name _Toc469402550: '4.HT PCCC'!$C$731
Name _Toc469402551: '4.HT PCCC'!$C$732
Name _Toc469402552: '4.HT PCCC'!$C$733
Name _Toc469402553: '4.HT PCCC'!$C$734
Name _Toc469402554: '4.HT PCCC'!$C$735
Name _Toc469402555: '4.HT PCCC'!$C$736
Name _Toc469402556: '4.HT PCCC'!$C$737
Name _Toc469402557: '4.HT PCCC'!$C$738
Name _Toc469402558: '4.HT PCCC'!$C$739
Name _Toc469402559: '4.HT PCCC'!$C$740
Name _Toc469402560: '4.HT PCCC'!$C$741
Name _Toc469402561: '4.HT PCCC'!$C$742
Name _Toc485909131: '4.HT PCCC'!$C$542
Name _Toc485909132: '4.HT PCCC'!$C$543
Name _Toc485909133: '4.HT PCCC'!$C$544
Name _Toc485909134: '4.HT PCCC'!$C$545
Name _Toc485909135: '4.HT PCCC'!$C$546
Name _Toc485909136: '4.HT PCCC'!$C$547
Name _Toc485909137: '4.HT PCCC'!$C$548
Name _Toc485909138: '4.HT PCCC'!$C$549
Name _Toc485909139: '4.HT PCCC'!$C$550
Name _Toc485909140: '4.HT PCCC'!$C$551
Name _Toc485909141: '4.HT PCCC'!$C$552
Name _Toc485909142: '4.HT PCCC'!$C$553
Name _Toc485909143: '4.HT PCCC'!$C$554
Name _Toc485909144: '4.HT PCCC'!$C$555
Name _Toc485909145: '4.HT PCCC'!$C$556
Name _Toc485909146: '4.HT PCCC'!$C$561
Name _Toc485909147: '4.HT PCCC'!$C$562
Name _Toc485909148: '4.HT PCCC'!$C$563
Name _Toc485909149: '4.HT PCCC'!$C$564
Name _Toc485909150: '4.HT PCCC'!$C$565
Name _Toc485909151: '4.HT PCCC'!$C$566
Name _Toc485909152: '4.HT PCCC'!$C$567
Name _Toc485909153: '4.HT PCCC'!$C$568
Name _Toc485909154: '4.HT PCCC'!$C$569
Name _Toc485909155: '4.HT PCCC'!$C$570
Name _Toc485909156: '4.HT PCCC'!$C$571
Name _Toc485909157: '4.HT PCCC'!$C$572
Name _Toc485909158: '4.HT PCCC'!$C$573
Name _Toc485909159: '4.HT PCCC'!$C$574
Name _Toc485909160: '4.HT PCCC'!$C$575
Name _Toc485909161: '4.HT PCCC'!$C$576
Name _Toc485909162: '4.HT PCCC'!$C$577
Name _Toc485909163: '4.HT PCCC'!$C$578
Name _Toc485909164: '4.HT PCCC'!$C$579

Sheet Mục Lục
B1: BẢNG ĐÁP ỨNG THÔNG SỐ KỸ THUẬT
A2: - Gói thầu: Gói 09-KS: Cung cấp, xây dựng và lắp đặt VTTB công trình Trạm 110kV Kế Sách và đường dây 110kV Phụng Hiệp-Kế Sách - Dự án: Trạm 110kV Kế Sách và đường dây 110kV Phụng Hiệp-Kế Sách
B3: TT | C3: Chủng loại vật tư, thiết bị | D3: Nguồn gốc/ Xuất xứ
B4: 1 | C4: =+'1.HT TTLL'!B1 -> HỆ THỐNG THÔNG TIN LIÊN LẠC (Switch distribute, Firewall, IP phone,…)
B5: 1.1 | C5: =+LOWER('1.HT TTLL'!B3) -> tủ thiết bị thông tin | D5: ='1.HT TTLL'!D4 -> TITSMART/Việt Nam
B6: 1.2 | C6: =+'1.HT TTLL'!B15 -> Switch distribute (layer 3) | D6: ='1.HT TTLL'!D16 & "/" & '1.HT TTLL'!D17 -> Advantech /Đài Loan
B7: 1.3 | C7: =+'1.HT TTLL'!B36 -> Firewall | D7: ='1.HT TTLL'!D37& "/"&'1.HT TTLL'!D38 -> Checkpoint/Đài Loan
B8: 1.4 | C8: =+'1.HT TTLL'!B72 -> IP Phone | D8: ='1.HT TTLL'!D73 & "/" &'1.HT TTLL'!D74 -> Cisco/VN/Trung Quốc
B9: 2 | C9: =+'2.HT SCADA'!B1 -> HỆ THỐNG SCADA TBA110kV
B10: 2.1 | C10: =+'2.HT SCADA'!B5 -> Gateway/RTU | D10: ='2.HT SCADA'!D10 -> TITSMART/Việt Nam
B11: 2.2 | C11: =+'2.HT SCADA'!B9 -> Tủ Gateway/RTU | D11: ='2.HT SCADA'!D10 -> TITSMART/Việt Nam
B12: 2.3 | C12: =+'2.HT SCADA'!B20 -> RTU | D12: ='2.HT SCADA'!D21 -> ABB /Đức
B13: 2.4 | C13: =+'2.HT SCADA'!B52 -> Phần mềm Gateway và HMI | D13: ='2.HT SCADA'!D53& "/" &'2.HT SCADA'!D54 -> Canada/Survalent
B14: 2.5 | C14: =+'2.HT SCADA'!B138 -> Thiết bị Ethernet Switch Access | D14: ='2.HT SCADA'!D139 -> Advantech/Trung Quốc
B15: 2.6 | C15: =+'2.HT SCADA'!B169 -> Máy tính HMI (Desktop) | D15: ='2.HT SCADA'!D170 -> Advantech/Trung Quốc
B16: 2.7 | C16: =+'2.HT SCADA'!B189 -> Màn hình LCD | D16: ='2.HT SCADA'!D190 -> Viewsonic/Trung Quốc
B17: 2.8 | C17: =+'2.HT SCADA'!B202 -> MÁY TÍNH Gateway | D17: ='2.HT SCADA'!D203 -> Advantech/Trung Quốc+ Đài Loan
B18: 2.9 | C18: =+'2.HT SCADA'!B232 -> Inverter 220VAC & 110VDC ® 220VAC, 2000VA (power supply): | D18: ='2.HT SCADA'!D233 -> IdealPlusing/Trung Quốc
B19: 2.10 | C19: =+'2.HT SCADA'!B250 -> Thiết bị đồng bộ thời gian GPS clock | D19: ='2.HT SCADA'!D251 -> Kyland/Trung Quốc
B20: 2.11 | C20: =+'2.HT SCADA'!B261 -> Thiết bị SCADA Firewall | D20: ='2.HT SCADA'!D262 -> Checkpoint/Đài Loan
B21: 2.12 | C21: =+'2.HT SCADA'!B297 -> MCB | D21: ='2.HT SCADA'!D298 -> Noark/Trung Quốc
B22: 2.13 | C22: =+'2.HT SCADA'!B302 -> Rơle trung gian | D22: ='2.HT SCADA'!D303 -> Phoenix/ Áo
B23: 2.14 | C23: =+'2.HT SCADA'!B306 -> Hàng kẹp | D23: ='2.HT SCADA'!D307 -> Phoenix/ Trung Quốc
B24: 2.15 | C24: =+'2.HT SCADA'!B309 -> Cáp điều khiển | D24: ='2.HT SCADA'!D310 -> Cadivi/Việt Nam
B25: 3 | C25: HỆ THỐNG CAMERA
B26: 3.1 | C26: =+'3.Camera'!B4 -> Camera hàng rào quanh trạm | D26: ='3.Camera'!D7& "/" &'3.Camera'!D8 -> Hikvision/Trung Quốc
B27: 3.2 | C27: =+'3.Camera'!B36 -> Camera PTZ Dome sân ngắt | D27: ='3.Camera'!D39& "/" &'3.Camera'!D40 -> Hikvision/Trung Quốc
B28: 3.3 | C28: =+'3.Camera'!B69 -> Camera cố định trong nhà | D28: ='3.Camera'!D72& "/" &'3.Camera'!D73 -> Hikvision/Trung Quốc
B29: 3.4 | C29: =+'3.Camera'!B101 -> Thiết bị mạng Switch tại TBA | D29: ='3.Camera'!D104& "/" &'3.Camera'!D105 -> Juniper/Trung Quốc
B30: 3.5 | C30: =+'3.Camera'!B133 -> Hệ thống kiểm soát ra vào | D30: ='3.Camera'!D136& "/" &'3.Camera'!D137 -> Soyal/Đài Loan + China
B31: 3.6 | C31: =+'3.Camera'!B199 -> Thiết bị Trung tâm truyền tin & điều khiển chuyên dụng | D31: ='3.Camera'!D202& "/" &'3.Camera'!D203 -> 3S/Việt Nam
B32: 3.7 | C32: =+'3.Camera'!B227 -> Thiết bị ghi hình và phân tích hình ảnh | D32: ='3.Camera'!D230& "/" &'3.Camera'!D231 -> Hikvision/Trung Quốc
B33: 3.8 | C33: =+'3.Camera'!B260 -> Thiết bị chuyển đổi nguồn điện | D33: ='3.Camera'!D263& "/" &'3.Camera'!D264 -> IdealPlusing/Trung Quốc
B34: 3.9 | C34: =+'3.Camera'!B283 -> Tủ Rack 19inche | D34: ='3.Camera'!D286& "/" &'3.Camera'!D287 -> TMC/Việt Nam
B35: 3.10 | C35: =+'3.Camera'!B300 -> Màn hình vi tính | D35: ='3.Camera'!D303& "/" &'3.Camera'!D304 -> ViewSonic/Trung Quốc
B36: 4 | C36: HỆ THỐNG PCCC
B37: 4.1 | C37: =+'4.HT PCCC'!B2 -> Hệ thống báo cháy
B38: =+'4.HT PCCC'!A5 -> 4.1.1 | C38: =+'4.HT PCCC'!B5 -> Tủ báo cháy trung tâm địa chỉ | D38: ='4.HT PCCC'!D8& "/" &'4.HT PCCC'!D9 -> Hochiki /United Kingdom
B39: =+'4.HT PCCC'!A42 -> 4.1.2 | C39: =+'4.HT PCCC'!B42 -> Đầu dò tích hợp khói và nhiệt loại địa chỉ | D39: ='4.HT PCCC'!D45& "/" &'4.HT PCCC'!D46 -> Hochiki/United Kingdom
B40: =+'4.HT PCCC'!A64 -> 4.1.3 | C40: =+'4.HT PCCC'!B64 -> Đầu dò nhiệt chống nổ | D40: ='4.HT PCCC'!D67& "/" &'4.HT PCCC'!D68 -> Hochiki/Japan
...

Sheet 1.HT TTLL
A1: 1. | B1: HỆ THỐNG THÔNG TIN LIÊN LẠC (Switch distribute, Firewall, IP phone,…)
A2: Stt | B2: Mô tả | C2: Yêu cầu | D2: Nhà thầu chào
A3: A | B3: TỦ THIẾT BỊ THÔNG TIN | C3: Nếu có
B4: - Nhà sản xuất/Nước sản xuất | C4: Nêu cụ thể | D4: TITSMART/Việt Nam
B5: - Mã hiệu | C5: Nêu cụ thể | D5: COM
B6: - Tiêu chuẩn | C6: Rack 19 inch | D6: Đáp ứng
B7: - Cấp bảo vệ (tối thiểu) | C7: IP.20 | D7: Đáp ứng
B8: - Cửa trước, cửa trong, cửa sau, các mặt bên, khóa … | C8: Kèm theo | D8: Đáp ứng
B9: - Bảng phân phối nguồn, cầu chì và & ngăn, cáp … | C9: Kèm theo | D9: Đáp ứng
B10: - Lắp ráp hòan chỉnh | C10: Có | D10: Đáp ứng
B11: - Điêu kiện môi trường | C11: TCN:68-149 hoặc tương đương | D11: Đáp ứng
B12: - Phụ kiện lắp đặt | C12: Kèm theo | D12: Đáp ứng
B13: Kích thước (Cao x rộng x sâu) mm | C13: Nêu cụ thể | D13: 2200x800x800
A14: B | B14: CÁC THIẾT BỊ LẮP TRONG TỦ
A15: B1 | B15: Switch distribute (layer 3)
B16: Nhà sản xuất | C16: Nêu cụ thể | D16: Advantech
B17: Nước sản xuất | C17: Nêu cụ thể | D17: Đài Loan
B18: Mã hiệu sản phẩm | C18: Nêu cụ thể | D18: EKI-8528-4XF-A
B19: Tiêu chuẩn | C19: - Đáp ứng chuẩn IEEE: 802.3z; 802.3ab; 802.3u; 802.1w; 802.1D, 802.1p, 802.1Q, 802.1 AB, 802.1s, 802.3ad, 802.3x. | D19: Đáp ứng
C20: - Đáp ứng Layer 3. | D20: Đáp ứng
C21: - Đáp ứng theo tiêu chuẩn IEEE 1613, IEC 61850-3, làm việc được trong môi trường TBA 110kV hoặc làm việc được trong môi trường có nguồn năng lượng phát xạ điện từ. | D21: Đáp ứng
C22: - Có chứng nhận KEMA hoặc của tổ chức quốc tế test theo tiêu chuẩn IEEE 1613 và IEC 61850. | D22: Đáp ứng
B23: Giao thức Ring | C23: STP/RSTP và hỗ trợ recovery time ≤ 20ms | D23: Đáp ứng
B24: Số cổng | C24: ≥ 04 x port 1000/10000Base(SFP) (bao gồm SFP 1000/10000 Mbps tương thích với hệ thống hiện hữu theo thiết kế). | D24: Đáp ứng
C25: ≥ 20 x port 10/100/1000 Base- SFP (bao gồm module quang, đồng theo triển khai kết nối thực tế trạm mới/ hiện hữu, module đồng bộ hãng sản xuất Switch, tương thích với hệ thống hiện hữu). | D25: Đáp ứng
B26: Hỗ trợ cấu hình Web: | C26: Có | D26: Đáp ứng
B27: Giao diện quản lý thiết bị: | C27: Ethernet RJ-45 | D27: Đáp ứng
B28: Nhiệt độ làm việc: | C28: 0℃ ~ +70℃ | D28: Đáp ứng
B29: Nguồn cung cấp | C29: - Số lượng cổng cấp nguồn: 02 nguồn hoạt động dự phòng 1:1
C30: - Mức điện áp: 110VDC hoặc 220VDC ±20% (phù hợp với nguồn tự dùng một chiều tại trạm) | D30: Đáp ứng
B31: Đảm bảo không có mã độc | C31: Nhà sản xuất phải có cam kết không có mã độc. | D31: Đáp ứng
B32: Tính năng bảo mật | C32: - IP source guard, DHCP snooping, ARP spoofing (hoặc ARP inspection) | D32: Đáp ứng
C33: - 802.1x, RADIUS, TACACS+, Access Control List, Storm Control (hoặc Storm protection) | D33: Đáp ứng
B34: Kích thước | C34: Tương thích dạng Rack 19", DIN-rail | D34: Đáp ứng
B35: Phụ kiện | C35: Trọn bộ phụ kiện, cáp kết nối, cáp nguồn đấu nối kèm theo đảm bảo tủ hoạt động an toàn, ổn định theo các chức năng yêu cầu | D35: Đáp ứng
A36: B2 | B36: Firewall
B37: Nhà sản xuất | C37: Nêu cụ thể | D37: Checkpoint
B38: Nước sản xuất | C38: Nêu cụ thể | D38: Đài Loan
B39: Mã hiệu sản phẩm | C39: Nêu cụ thể | D39: CPAP-SG1575R
B40: Số lượng cổng | C40: Giao tiếp mạng LAN: tối thiểu 06 cổng Ethernet RJ-45 10/100Mbps auto sense | D40: Đáp ứng
...

Sheet 2.HT SCADA
A1: 2. | B1: HỆ THỐNG SCADA TBA110kV
A2: Stt | B2: Mô tả | C2: Yêu cầu | D2: Nhà thầu chào
A3: I | B3: Hệ thống SCADA
B4: Nhà cung cấp (tích hợp) | C4: Nêu cụ thể | D4: TITSMART
B5: Gateway/RTU | C5: (Mã hiệu/nhà sản xuất) Nêu cụ thể | D5: ECU-4784/Advantech
B6: Phần mềm SCADA | C6: (Phiên bản/nhà sản xuất) Nêu cụ thể | D6: SurvalanONE / Survalent
B7: Đặc tính kỹ thuật chung của hệ thống SCADA trạm | C7: Đáp ứng yêu cầu kỹ thuật chi tiết tại Phần B | D7: Đáp ứng
A8: II | B8: Tủ thiết bị SCADA
A9: 1 | B9: Tủ Gateway/RTU
B10: - Nhà sản xuất/Nước sản xuất | C10: Nêu cụ thể | D10: TITSMART/Việt Nam
B11: - Mã hiệu | C11: Nêu cụ thể | D11: GW
B12: Cấp bảo vệ tối thiểu | C12: IP 41 | D12: Đáp ứng
B13: Kích thước (Cao x rộng x sâu) mm | C13: Nêu cụ thể | D13: 2200x800x800
B14: Nhiệt độ môi trường xung quanh lớn nhất | C14: 400C | D14: Đáp ứng
B15: Độ ẩm tương đối lớn nhất | C15: 0.9 | D15: Đáp ứng
B16: Điều kiện khí hậu | C16: Nhiệt đới | D16: Đáp ứng
B17: Tiêu chuẩn quản lý chất lượng | C17: ISO 9001 hoặc tương đương | D17: Đáp ứng
B18: Sơ đồ tổng quát, lắp đặt tủ của nhà sản xuất | C18: có | D18: Đáp ứng
A19: 2 | B19: Các thiết bị trong tủ
A20: 2.1 | B20: RTU
B21: - Nhà sản xuất/Nước sản xuất | C21: Nêu cụ thể | D21: ABB /Đức
B22: - Mã hiệu | C22: Nêu cụ thể | D22: RTU560
B23: Nguồn: 110VDC ±20% | C23: 2 card làm việc ở chế độ dự phòng nóng 1:1 (redundancy) | D23: Đáp ứng
B24: CPU: tối thiểu 32 bit, tốc độ cao | C24: 04 CPU làm việc ở chế độ dự phòng nóng(redundancy) 1:1 Có thể mở rộng lên 06 CPU | D24: Đáp ứng
B25: Kết nối về mạng IP Network nội tỉnh hoặc TTĐK thực hiện điều khiển xa | C25: 2 cổng kết nối độc lập về vật lý | D25: Đáp ứng
B26: Kết nối với 2 Ethernet Swich khác nhau của hệ thống mạng IEC61850 | C26: 2 cổng kết nối độc lập về vật lý | D26: Đáp ứng
B27: Bộ nhớ trung gian | C27: Lưu trữ thông tin thay đổi trạng thái ít nhất 10 ngày trong trường hợp mất kết nối trung tâm điều khiển. | D27: Đáp ứng
B28: Bộ nhớ cơ sở dữ liệu | C28: Duy trì ít nhất 30 ngày trong trường hợp không được cung cấp điện | D28: Đáp ứng
B29: Số lượng datapoint | C29: > 1500 | D29: Đáp ứng
B30: Thời gian đáp ứng tối thiểu đối với tín hiệu số | C30: 10ms | D30: Đáp ứng
B31: Thời gian đáp ứng tối thiểu đối với tín hiệu đo lường | C31: 2s | D31: Đáp ứng
B32: Độ trễ của tín hiệu: | C32: ≤ 4s | D32: Đáp ứng
... B34: Có chứng nhận KEMA test/tương đương theo tiêu chuẩn IEEE1613 và IEC61850 | C34: Có | D34: Đáp ứng
B35: * Các chức năng:
B36: Hỗ trợ các giao thức: IEC61850 phiên bản 2 hoặc mới hơn và tương thích với hệ thống của trạm, IEC 60870-5-104, Modbus RTU/Modbus TCP | C36: Có | D36: Đáp ứng
B37: Hỗ trợ đồng bộ SNTP cho đồng hồ GPS | C37: Có | D37: Đáp ứng
B38: Đồng bộ thời gian | C38: Cấp chính xác: +/-10-6 (84,6ms/ngày) | D38: Đáp ứng
B39: Hỗ trợ tính năng bảo trì từ xa: giám | C39: Có | D39: Đáp ứng
B40: sát, chuẩn đoán sự cố, nạp CSDL… | D40: Đáp ứng
B41: Lưu trữ thông tin sự cố, các giá trị tính toán và đo lường. | C41: Có | D41: Đáp ứng
...

Sheet 3.Camera
A1: 3. | B1: Hệ thống Camera
A2: STT | B2: Nội dung yêu cầu | D2: Nhà thầu chào
B3: Mô tả | C3: Yêu cầu kỹ thuật
A4: 3.1 | B4: Camera hàng rào quanh trạm
A5: A | B5: Yêu cầu chung
A6: 1 | B6: Mã sản phẩm | C6: Nhà thầu khai báo | D6: DS-2DE4225IW
A7: 2 | B7: Nhà sản xuất | C7: Nhà thầu khai báo | D7: Hikvision
A8: 3 | B8: Nước sản xuất | C8: Nhà thầu khai báo | D8: Trung Quốc
A9: 4 | B9: Catalog theo mã thiết bị | C9: Nhà thầu xuất trình | D9: Đáp ứng
A10: 5 | B10: Chứng nhận CO | C10: Có (nếu hàng hóa nước ngoài) | D10: Đáp ứng
A11: 6 | B11: Chứng nhận CQ hoặc Chứng nhận xuất xưởng | C11: Có | D11: Đáp ứng
A12: 7 | B12: Tiêu chuẩn tác động môi trường | C12: CE hoặc tương đương | D12: Đáp ứng
A13: 8 | B13: Tiêu chuẩn quản lý chất lượng sản phẩm | C13: ISO 9001 | D13: Đáp ứng
A14: 9 | B14: Chất lượng thiết bị | C14: Mới 100% | D14: Đáp ứng
A15: 10 | B15: Thời gian bảo hành | C15: 24 tháng kể từ khi ký biên bản nghiệm thu và đưa vào sử dụng. | D15: Đáp ứng
A16: 11 | B16: Năm sản xuất | C16: 2025 | D16: Đáp ứng
A17: 12 | B17: Các yêu cầu kỹ thuật chung trình bày trong phần I và III | C17: Đáp ứng | D17: Đáp ứng
A18: B | B18: Yêu cầu kỹ thuật chi tiết
A19: 1 | B19: Cảm biến hình ảnh | C19: ≥ 1/ 2.8’’2 Megapixel CMOS | D19: Đáp ứng
A20: 2 | B20: Độ nhạy sáng | C20: ≤ 0.01Lux | D20: Đáp ứng
A21: 3 | B21: Tích hợp hồng ngoại | C21: Đáp ứng (Tối thiểu 100m) | D21: Đáp ứng
A22: 4 | B22: Chuẩn nén | C22: Hỗ trợ H264 hoặc cao hơn | D22: Đáp ứng
A23: 5 | B23: Độ phân giải | C23: ≥ 1920*1080 | D23: Đáp ứng
A24: 6 | B24: Tốc độ khung hình | C24: ≥ 25fps | D24: Đáp ứng
A25: 7 | B25: Ethernet | C25: RJ-45 (10/100Base-T) | D25: Đáp ứng
A26: 8 | B26: Giao thức | C26: IPv4/IPv6, HTTP, TCP/IP, UDP, IGMP, RTSP, RTP, SMTP, NTP, DHCP | D26: Đáp ứng
A27: 9 | B27: Khả năng tương thích | C27: ONVIF | D27: Đáp ứng
A28: 10 | B28: Nguồn cung cấp | C28: Hỗ trợ PoE | D28: Đáp ứng
A29: 11 | B29: Tiêu chuẩn bảo vệ | C29: ≥ IP66 | D29: Đáp ứng
A30: 12 | B30: Nhiệt độ hoạt động | C30: Tối thiểu ≤ 0º | D30: Đáp ứng
C31: Tối đa ≥ 60º | D31: Đáp ứng
A32: 13 | B32: Độ ẩm hoạt động | C32: Tối thiểu ≤ 10% | D32: Đáp ứng
C33: Tối đa ≥ 85% | D33: Đáp ứng
A34: 14 | B34: Phát hiện vượt hàng rào và phát hiện xâm nhập khu vực cấm | C34: Có sẵn | D34: Đáp ứng
A35: 15 | B35: Phụ kiện đấu nối, bộ chuyển đổi nguồn đấu nối với nguồn tại trạm, phụ kiện treo gá … | C35: Đáp ứng đầy đủ | D35: Đáp ứng
A36: 3.2 | B36: Camera PTZ Dome sân ngắt
A37: A | B37: Yêu cầu chung
A38: 1 | B38: Mã sản phẩm | C38: Nhà thầu khai báo | D38: DS-2DE4225IW
A39: 2 | B39: Nhà sản xuất | C39: Nhà thầu khai báo | D39: Hikvision
A40: 3 | B40: Nước sản xuất | C40: Nhà thầu khai báo | D40: Trung Quốc
...

Sheet 4.HT PCCC
A1: 4. | B1: Thiết bị PCCC
A2: 4.1 | B2: Hệ thống báo cháy
A3: STT | B3: Nội dung yêu cầu | D3: Nhà thầu chào
B4: Mô tả | C4: Yêu cầu kỹ thuật
A5: 4.1.1 | B5: Tủ báo cháy trung tâm địa chỉ
A6: A | B6: Yêu cầu chung
A7: 1 | B7: Mã sản phẩm | C7: Nhà thầu khai báo | D7: LA302H1-10
A8: 2 | B8: Nhà sản xuất | C8: Nhà thầu khai báo | D8: Hochiki
A9: 3 | B9: Nước sản xuất | C9: Nhà thầu khai báo | D9: United Kingdom
A10: 4 | B10: Catalog theo mã thiết bị | C10: Nhà thầu xuất trình | D10: Đáp ứng
A11: 5 | B11: Chứng nhận CO | C11: Có (nếu hàng hóa nước ngoài) | D11: Đáp ứng
A12: 6 | B12: Chứng nhận CQ hoặc Chứng nhận xuất xưởng | C12: Có | D12: Đáp ứng
A13: 7 | B13: Tiêu chuẩn tác động môi trường | C13: CE hoặc tương đương | D13: Đáp ứng
A14: 8 | B14: Tiêu chuẩn quản lý chất lượng sản phẩm | C14: ISO 9001 | D14: Đáp ứng
A15: 9 | B15: Chất lượng thiết bị | C15: Mới 100% | D15: Đáp ứng
A16: 10 | B16: Thời gian bảo hành | C16: 12 tháng kể từ khi ký biên bản nghiệm thu và đưa vào sử dụng. | D16: Đáp ứng
A17: 12 | B17: Năm sản xuất | C17: Đơn vị tự đề xuất đảm bảo sản phẩm có thời gian sản xuất phù hợp | D17: Đáp ứng
A18: B | B18: Yêu cầu kỹ thuật chi tiết
A19: 1 | B19: Số lượng input | C19: Đáp ứng thu thập tín hiệu cảm biến báo nhiệt; báo khói….; 2 loop x (≥159 địa chỉ). | D19: Đáp ứng
A20: 2 | B20: Số kênh giám sát | C20: 2 loop x (≥159 địa chỉ) | D20: Đáp ứng
A21: 3 | B21: Chất liệu vỏ | C21: Kim loại | D21: Đáp ứng
A22: 4 | B22: Nguồn cấp: | C22: - Điện lưới 220VAC-50Hz-10A; | D22: Đáp ứng
C23: - Acquy khô 24VDC-16AH; | D23: Đáp ứng
C24: - Bộ xạc tự động cho bình Accu loại tích hợp trong tủ báo cháy trung tâm. | D24: Đáp ứng
A25: 5 | B25: Có khả năng tích hợp tín hiệu báo cháy vào phần mềm camera an ninh tại TTĐK thông qua kênh truyền camera | C25: - Tích hợp cổng giao diện RS-232 để lập trình thông qua máy tính và kết nối với máy in; | D25: Đáp ứng
C26: - Giao tiếp với mạng máy tính nội bộ qua kết nối RJ45; | D26: Đáp ứng
C27: - Giao tiếp với phần mềm đồ họa; | D27: Đáp ứng
C28: - Giao tiếp với hệ thống điện; | D28: Đáp ứng
C29: - Giao tiếp với hệ thống camera; | D29: Đáp ứng
C30: - Tủ báo cháy trung tâm có chức năng hiển thị, kiểm soát và điều khiển hệ thống PCCC của trạm từ xa qua đường truyền mạng nội bộ từ máy tính của trung tâm điều khiển xa. | D30: Đáp ứng
A31: 6 | B31: Lập trình | C31: - Có thể lập trình qua các nút nhấn trên tủ hoặc kết nối với máy tính thông qua phần mềm. | D31: Đáp ứng
C32: - Phần mềm lập trình sử dụng phương thức lập trình đồ họa, trực quan, dễ sử dụng. | D32: Đáp ứng
C33: - Có thể sử dụng bản đồ, đồ họa, âm thanh để giám sát và báo động. | D33: Đáp ứng
C34: - Cho phép cập nhật lại Firmware từ phần mềm. | D34: Đáp ứng
C35: - Linh hoạt với khả năng lập trình kết quả Cause & Effect: | D35: Đáp ứng
C36: • Nguyên nhân và hành động; | D36: Đáp ứng
C37: • Chức năng vô hiệu hoá cấu hình; | D37: Đáp ứng
C38: - Chế độ kiểm tra cấu hình. | D38: Đáp ứng
A39: 7 | B39: Nhiệt độ làm việc | C39: Tối thiểu ≤ 0°C Tối đa ≥ 70°C | D39: Đáp ứng
A40: 8 | B40: Độ ẩm cho phép | C40: 93% ± 2% RH (không ngưng tụ) at 32°C ± 2°C (90°F ± 3°F). | D40: Đáp ứng
...

Sheet 5.RS232RS485
A1: 5. | B1: Bộ chuyển đổi RS232→RS485
A2: Stt | B2: Mô tả | C2: Yêu cầu | D2: Nhà thầu chào
A3: 1 | B3: Nhà sản xuất/Nước sản xuất | C3: Nêu cụ thể | D3: 3onedata/Trung Quốc
A4: 2 | B4: Mã hiệu | C4: Nêu cụ thể | D4: TLC485
A5: 3 | B5: Nguồn:. | C5: Lấy từ cổng RS232, không cần nguồn ngoài | D5: Đáp ứng
A6: 4 | B6: Chuyển đổi tín hiệu | C6: RS232 sang RS485 | D6: Đáp ứng
A7: 5 | B7: Cắm và chạy (Plug and play) | C7: Có khả năng cắm nóng thiết bị tự động định dạng dữ liệu. | D7: Đáp ứng
A8: 6 | B8: Điểm đếm | C8: Đa điểm, hỗ trợ 128 điểm loopback hoặc tương đương | D8: Đáp ứng
A9: 7 | B9: Quay vòng dữ liệu | C9: Tự động, không đòi hỏi kiểm soát luồng dữ liệu. | D9: Đáp ứng

Sheet 6.Connector RS232
A1: 6. | B1: Connector RS232
A2: Stt | B2: Mô tả | C2: Yêu cầu | D2: Nhà thầu chào
A3: 1 | B3: Nhà sản xuất/Nước sản xuất | C3: Nêu cụ thể | D3: HD-Link/Trung Quốc
A4: 2 | B4: Mã hiệu | C4: Nêu cụ thể | D4: D-SUB-DB9-DB25
A5: 3 | B5: Kết nối từ modul của công tơ (cổng 25 chân) đến cổng RS232 của máy tính công nghiệp (cổng 9 chân) | C5: - Cổng có thể chịu được nhiệt hơn 5000C trong thời gian ngắn, chống thấm nước, chống thấm khí O2, CO2, N2…, độ bền cơ học cao, dễ thao tác đấu nối | D5: Đáp ứng

Sheet 7.CAT6
A1: 7. | B1: Cáp mạng CAT6
A2: Stt | B2: Mô tả | C2: Yêu cầu | D2: Nhà thầu chào
A3: 1 | B3: Nhà sản xuất/Nước sản xuất | C3: Nêu cụ thể | D3: Commscope/Trung Quốc
A4: 2 | B4: Mã hiệu | C4: Nêu cụ thể | D4: 884024508/10
A5: 3 | B5: Loại dây | C5: Tối thiểu AMP cat6 | D5: F/UTP CAT6
A6: 4 | B6: Tín hiệu nhận được | C6: 70-80m | D6: Đáp ứng
A7: 5 | B7: Vỏ | C7: Chống cháy, chống nhiễu | D7: Đáp ứng
A8: 6 | B8: Tốc độ hỗ trợ | C8: Gigabit Ethernet hoặc tương đương | D8: Đáp ứng

Sheet 8.Module SFP
A1: 8. | B1: Thiết bị module SFP
A2: Stt | B2: Mô tả | C2: Yêu cầu | D2: Nhà thầu chào
A3: 1 | B3: Nhà sản xuất/Nước sản xuất | C3: Nêu cụ thể | D3: WT/Handar/Trung Quốc
A4: 2 | B4: Mã hiệu | C4: Nêu cụ thể | D4: SFP
A5: 3 | B5: Bước sóng công tác: | C5: 1310nm/1550nm | D5: Đáp ứng
A6: 4 | B6: Cự ly truyền dẫn: | C6: 40km-60km | D6: Đáp ứng
A7: 5 | B7: Giao diện điện: | C7: G703/120 Ohm | D7: Đáp ứng
A8: 6 | B8: Lắp đặt: | C8: Lắp đặt trên khe Switch. | D8: Đáp ứng
B9: Phụ kiện | C9: - Trọn bộ phụ kiện, phần mềm, cáp kết nối, cáp nhảy quang, đầu nối… | D9: Đáp ứng

Sheet 9.ODF
A1: 9. | B1: Hộp đầu cuối cáp quang với ODF
A2: STT | B2: Mô tả | C2: Yêu cầu | D2: Nhà thầu chào
A3: 1 | B3: Nhà sản xuất/Nước sản xuất | C3: Nêu cụ thể | D3: TITSMART/Việt Nam
A4: 2 | B4: Mã hiệu | C4: Nêu cụ thể | D4: ODF24
A5: 3 | B5: Ứng dụng | C5: - Cho đấu nối đầu cuối và phân phối 24 sợi quang. | D5: Đáp ứng
A6: 4 | B6: Lắp đặt | C6: - Trong tủ 19” | D6: Đáp ứng
A7: 5 | B7: Đầu nối | C7: - SC/APC | D7: Đáp ứng
A8: 6 | B8: Ngõ ra cáp | C8: - Sau tủ | D8: Đáp ứng
A9: 7 | B9: Phần cứng lắp đặt | C9: - Đầy đủ 24 Pigtail SC/APC , cuộn nối cáp, máng bảo vệ chống co ngót do nhiệt, bộ phận nối và các phụ kiện thích hợp, v.v… | D9: Đáp ứng
C10: - Khay hàn, dây nối quang (pigtail) đơn mode, đầu giao tiếp APC tốt (có suy hao tiếp xúc và phản xạ ngược thấp) và các phụ kiện lắp đặt hợp bộ đầy đủ để phù hợp với thực tế sử dụng. | D10: Đáp ứng

Sheet 10.Cáp NMOC
A1: 10. | B1: Cáp quang Non-metallic (FO)
A2: Stt | B2: Mô tả | C2: Yêu cầu | D2: Nhà thầu chào
A3: 1 | B3: Nhà sản xuất/Nước sản xuất | C3: Nêu cụ thể | D3: Postel/Việt Nam
A4: 2 | B4: Mã hiệu | C4: Nêu cụ thể | D4: CPKL
B5: Các đặc tính kỹ thuật sợi cáp quang:
A6: 3 | B6: Tiêu chuẩn: | C6: ITU-T G.652D | D6: Đáp ứng
A7: 4 | B7: Loại | C7: Đơn mode | D7: Đáp ứng
A8: 5 | B8: Số sợi | C8: 24 | D8: Đáp ứng
A9: 6 | B9: Bước sóng làm việc | C9: 1310nm -1550nm | D9: Đáp ứng
A10: 7 | B10: Đường kính trường mode | C10: (7,8 ÷ 9,5) mm ±10% | D10: Đáp ứng
A11: 8 | B11: Sai số không đồng tâm của trường mode | C11: £ 0,6mm | D11: Đáp ứng
A12: 9 | B12: Đường kính lớp bao lõi | C12: 125mm ±2mm | D12: Đáp ứng
A13: 10 | B13: Độ không tròn đều của vỏ | C13: £ 1% | D13: Đáp ứng
A14: 11 | B14: Đường kính lớp vỏ bọc ngoài | C14: 245mm ±1mm | D14: Đáp ứng
A15: 12 | B15: Hệ số suy hao tại bước sóng 1310nm | C15: < 0,4 dB/km | D15: Đáp ứng
A16: 13 | B16: Hệ số suy hao tại bước sóng 1550nm | C16: < 0,35 dB/km | D16: Đáp ứng
A17: 14 | B17: Hệ số tán sắc tại bước sóng 1310nm | C17: < 3,5 ps/nm.km | D17: Đáp ứng
A18: 15 | B18: Hệ số tán sắc tại bước sóng 1550nm | C18: < 18 ps/nm.km | D18: Đáp ứng
A19: 16 | B19: Bước sóng cắt | C19: lcc £ 1260nm | D19: Đáp ứng
A20: 17 | B20: Mức thử nghiệm sợi quang | C20: £ 1% sức căng | D20: Đáp ứng
A21: 18 | B21: Mã màu | C21: EIA/TIA RS-598 | D21: Đáp ứng
B22: * Đặc tính kỹ thuật sợi cáp:
A23: 19 | B23: Loại | C23: Non-metallic lắp đặt trong ống và chôn trực tiếp trong đất | D23: Đáp ứng
A24: 20 | B24: Lực kéo đứt (RTS) | C24: ³ 3 kN | D24: Đáp ứng
A25: 21 | B25: Tải trọng phá hoại (kN) | C25: Nêu cụ thể | D25: > 10.000 N
A26: 22 | B26: Bán kính uốn cong tối thiểu trong quá trình lắp đặt | C26: 20 lần đường kính ngoài. | D26: Đáp ứng
A27: 23 | B27: Bán kính uốn cong tối thiểu khi lắp đặt treo | C27: 10 lần đường kính ngoài | D27: Đáp ứng
A28: 24 | B28: Đường kính ngoài (mm) | C28: Nêu cụ thể | D28: 12.5 mm ± 0.5 mm
A29: 25 | B29: Loại vỏ bọc | C29: Chống gặm nhấm & mối mọt HDPE | D29: Đáp ứng
A30: 26 | B30: Chống nước | C30: IEC-794-1-F5 | D30: Đáp ứng
A31: 27 | B31: Nhiệt độ làm việc | C31: (-10 ¸ +80) 0C | D31: Đáp ứng
A32: 28 | B32: Độ ẩm tuyệt đối | C32: (0 ¸ 100) % | D32: Đáp ứng
A33: 29 | B33: Tuổi thọ thiết kế của cáp. | C33: Tối thiểu 20 năm | D33: Đáp ứng

Sheet 11.HT Đk máy tính
A1: 11. | B1: Hệ thống điều khiển máy tính
A2: Stt | B2: Mô tả | C2: Yêu cầu | D2: Nhà thầu chào
A3: I | B3: Hệ thống Máy tính HMI
A4: I.1 | B4: Máy tính HMI (Desktop)
B5: - Nhà sản xuất/Nước sản xuất | C5: Nêu cụ thể | D5: Advantech/Trung Quốc
B6: - Mã hiệu | C6: Nêu cụ thể | D6: IPC-7130
B7: Loại: | C7: Máy tính để bàn Desktop | D7: Đáp ứng
B8: Cấu hình:
B9: - Mainboard: | C9: Tối thiểu Intel chipset G41 hoặc tương đương; Bus: 1333 MHz | D9: Đáp ứng
B10: - Bộ xử lý: | C10: Tối thiểu Intel Core i5; CPUs: > 2,8 GHz ; Bus: 1333 MHz; 3MB L2 Cache Memory hoặc cao hơn | D10: Đáp ứng
B11: - Số lượng bộ xử lý: | C11: 01 | D11: Đáp ứng
B12: - Bộ nhớ | C12: DDR-3: 2x4GB, bus: | D12: 8GB DDR4 3200Mhz
B13: - Khe mở rộng | C13: 1333MHz hoặc cao hơn, với 2 khe (02) DIM | D13: Đáp ứng
C14: 02 PCI và 02 PCI-Ex hoặc 04 cổng PCI-Ex | D14: Đáp ứng
B15: - Khay ổ cứng | C15: Hỗ trợ nhiều khay (tối thiểu 02 khay) | D15: Đáp ứng
B16: - Dung lượng ổ cứng | C16: SDD storage: tối thiểu 250Gb | D16: Đáp ứng
B17: - Đầu đọc | C17: DVD-ROM/CD-DVD RW Combo | D17: Đáp ứng
B18: - Giao diện mạng | C18: Dual Gigabit Ethernet | D18: Đáp ứng
B19: - Bộ xử lý đồ họa | C19: On board hoặc external, tối thiểu (02) cổng giao diện: D- sub/HDMI, và có chức năng hiển thị trên 2 màn hình trong cùng thời điểm | D19: Đáp ứng
B20: - Cổng USB | C20: 4x USB port | D20: Đáp ứng
B21: - Thiết bị ngoại vi | C21: Standard keyboard, USB Optical Scroll Mouse | D21: Đáp ứng
B22: - Nguồn cung cấp | C22: Ngõ vào: 180-240 VAC | D22: Đáp ứng
B23: - Phần mềm hệ thống (OS) Cam kết không chứa mã độc từ nhà sản xuất và có phần mềm diệt virus | C23: Theo mục yêu cầu kỹ thuật thiết bị | D23: Đáp ứng
A24: I.2 | B24: Màn hình LCD
B25: - Nhà sản xuất/Nước sản xuất | C25: Nêu cụ thể | D25: Viewsonic/Trung Quốc
B26: - Mã hiệu | C26: Nêu cụ thể | D26: VA2215
B27: Loại: | C27: Màn hình LCD | D27: Đáp ứng
B28: Thông số kỹ thuật:
B29: - Cỡ màn hình | C29: > 21 inches | D29: Đáp ứng
B30: - Kỹ thuật màn hình | C30: LCD hoặc cao hơn | D30: Đáp ứng
B31: - Độ phân giải | C31: 1920 x 1080 | D31: Đáp ứng
B32: - Thời gian xử lý: | C32: < 5ms | D32: Đáp ứng
B33: - Độ tương phản | C33: > 1000:1 | D33: Đáp ứng
B34: - Đấu nối | C34: Tối thiểu 01 cổng D-sub/HDMI | D34: Đáp ứng
B35: - Chức năng ngoài | C35: Điều khiển số | D35: Đáp ứng
B36: - Nguồn cung cấp | C36: 180-240VAC | D36: Đáp ứng
A37: II | B37: Máy tính Engineering
B38: - Nhà sản xuất/Nước sản xuất | C38: Nhà thầu nêu cụ thể | D38: Advantech/Trung Quốc
B39: - Mã hiệu | C39: Nhà thầu nêu cụ thể | D39: ACP-4320
B40: Loại: | C40: Máy dạng Rack | D40: Đáp ứng
...

Sheet 12.Ethernet Switch 
A1: 12. | B1: Thiết bị Ethernet Switch Distribute
A2: Stt | B2: Mô tả | C2: Yêu cầu | D2: Nhà thầu chào
A3: I | B3: Hệ thống Máy tính HMI
A4: 1 | B4: Nhà sản xuất/Nước sản xuất | C4: Nêu cụ thể | D4: Advantech / Đài Loan
A5: 2 | B5: Mã hiệu | C5: Nêu cụ thể | D5: EKI-8528-4XF-A
A6: 3 | B6: Giao diện quản lý thiết bị: | C6: Ethernet RJ-45 | D6: Đáp ứng
A7: 4 | B7: Số cổng (Đối với swicth Distribute): | C7: - ≥ 04 x port 1000/10000Base(SFP) (bao gồm SFP 1000/10000 Mbps tương thích với hệ thống hiện hữu theo thiết kế). | D7: Đáp ứng
C8: - ≥ 20 x port 10/100/1000 Base- SFP (bao gồm module quang, đồng theo triển khai kết nối thực tế trạm mới/ hiện hữu, module đồng bộ hãng sản xuất Switch, tương thích với hệ thống hiện hữu). | D8: Đáp ứng
A9: 5 | B9: Tiêu chuẩn: | C9: - Đáp ứng chuẩn IEEE: 802.3z; 802.3ab; 802.3u; 802.1w; 802.1D, 802.1p, 802.1Q, 802.1s, 802.3ad, 802.3x. | D9: Đáp ứng
C10: - Đáp ứng Layer 3 routing (đối với switch distribute). | D10: Đáp ứng
C11: - Đáp ứng theo tiêu chuẩn IEEE1613, IEC 61850-3, làm việc được trong môi trường TBA 110kV hoặc làm việc được trong môi trường có nguồn năng lượng phát xạ điện từ. | D11: Đáp ứng
C12: - Có chứng nhận KEMA hoặc của tổ chức quốc tế test theo tiêu chuẩn IEEE1613 và IEC61850. | D12: Đáp ứng
A13: 7 | B13: Hỗ trợ cấu hình Web: | C13: Có | D13: Đáp ứng
A14: 8 | B14: Nhiệt độ làm việc: | C14: 0℃ ~ +70℃ | D14: Đáp ứng
A15: 9 | B15: Nguồn cung cấp: | C15: - Số lượng cổng cấp nguồn: 2 nguồn hoạt động dự phòng 1:1. | D15: Đáp ứng
C16: - Mức điện áp: 110VDC ±20%. | D16: Đáp ứng
A17: 10 | B17: Đảm bảo không có mã độc | C17: Nhà sản xuất phải có cam kết không có mã độc. | D17: Đáp ứng
A18: 11 | B18: Phụ kiện | C18: Trọn bộ phụ kiện, cáp kết nối, cáp nguồn đầu nối kèm theo. | D18: Đáp ứng
A19: 12 | B19: Tính năng bảo mật | C19: IP source guard, DHCP snooping, ARP spoofing (hoặc ARP inspection). | D19: Đáp ứng
C20: 802.1x, RADIUS, TACACS+, Access Control List, Storm Control (hoặc Storm protection). | D20: Đáp ứng

Sheet 13.Dây nhảy quang
A1: 13. | B1: Dây nhảy quang
A2: Stt | B2: Mô tả | C2: Yêu cầu | D2: Nhà thầu chào
A3: 1 | B3: Nhà sản xuất/Nước sản xuất | C3: Nêu cụ thể | D3: TITSMART/Việt Nam
A4: 2 | B4: Mã hiệu | C4: Nêu cụ thể | D4: DNQ
A5: 3 | B5: Đấu nối | C5: SC/APC (phù hợp với thiết bị) | D5: Đáp ứng
A6: 4 | B6: Sợi quang | C6: Đơn mode | D6: Đáp ứng
A7: 5 | B7: Tổn hao do nối ngoài | C7: ≤ 0,2 dB | D7: Đáp ứng
A8: 6 | B8: Chiều dài tổng | C8: ≥ 20 m (đấu nối thiết bị truyền dẫn quang) | D8: Đáp ứng
C9: ≥ 30 m (đấu nối 87L) | D9: Đáp ứng

Sheet 14.Module ghép stack
A1: 14. | B1: Thiết bị module ghép stack
A2: Stt | B2: Mô tả | C2: Yêu cầu | D2: Nhà thầu chào
A3: 1 | B3: Nhà sản xuất/Nước sản xuất | C3: Nêu cụ thể | D3: Cisco/Trung Quốc
A4: 2 | B4: Mã hiệu | C4: Nêu cụ thể | D4: STACK-KIT
A5: 3 | B5: Khoảng cách xếp chồng giữa các switch: | C5: Nêu cụ thể | D5: Tối đa 3m (Tùy chọn cáp 0.5m, 1m hoặc 3m)
A6: 4 | B6: Số cổng | C6: Nêu cụ thể | D6: 02 cổng StackWise 440
A7: 5 | B7: Băng thông: | C7: Nêu cụ thể | D7: 440 Gbps
A8: 6 | B8: Số lượng xếp chồng tối đa: | C8: Nêu cụ thể | D8: 08 thiết bị
B9: Phụ kiện | C9: - Trọn bộ cáp kết nối, đầu nối… | D9: Đáp ứng
